01/04/2021 08:43:27|INFO    |root                            |BAZARR is started and waiting for request on http://0.***.***.***:6767/bazarr|
01/04/2021 09:08:58|INFO    |root                            |BAZARR is started and waiting for request on http://0.***.***.***:6767/bazarr|
01/04/2021 09:15:21|INFO    |root                            |BAZARR is started and waiting for request on http://0.***.***.***:6767/bazarr|
01/04/2021 10:05:56|ERROR   |root                            |Error trying to get releases from Github. Connection Error.|'Traceback (most recent call last):\n  File "/app/bazarr/bazarr/../libs/urllib3/connection.py", line 159, in _new_conn\n    conn = connection.create_connection(\n  File "/app/bazarr/bazarr/../libs/subliminal_patch/http.py", line 366, in patched_create_connection\n    return _orig_create_connection((host, port), *args, **kwargs)\n  File "/app/bazarr/bazarr/../libs/urllib3/util/connection.py", line 80, in create_connection\n    raise err\n  File "/app/bazarr/bazarr/../libs/urllib3/util/connection.py", line 70, in create_connection\n    sock.connect(sa)\nConnectionRefusedError: [Errno 111] Connection refused\n\nDuring handling of the above exception, another exception occurred:\n\nTraceback (most recent call last):\n  File "/app/bazarr/bazarr/../libs/urllib3/connectionpool.py", line 600, in urlopen\n    httplib_response = self._make_request(conn, method, url,\n  File "/app/bazarr/bazarr/../libs/urllib3/connectionpool.py", line 344, in _make_request\n    self._validate_conn(conn)\n  File "/app/bazarr/bazarr/../libs/urllib3/connectionpool.py", line 843, in _validate_conn\n    conn.connect()\n  File "/app/bazarr/bazarr/../libs/urllib3/connection.py", line 316, in connect\n    conn = self._new_conn()\n  File "/app/bazarr/bazarr/../libs/urllib3/connection.py", line 168, in _new_conn\n    raise NewConnectionError(\nurllib3.exceptions.NewConnectionError: <urllib3.connection.VerifiedHTTPSConnection object at 0x7f55e94f2cd0>: Failed to establish a new connection: [Errno 111] Connection refused\n\nDuring handling of the above exception, another exception occurred:\n\nTraceback (most recent call last):\n  File "/app/bazarr/bazarr/../libs/requests/adapters.py", line 439, in send\n    resp = conn.urlopen(\n  File "/app/bazarr/bazarr/../libs/urllib3/connectionpool.py", line 640, in urlopen\n    retries = retries.increment(method, url, error=e, _pool=self,\n  File "/app/bazarr/bazarr/../libs/urllib3/util/retry.py", line 399, in increment\n    raise MaxRetryError(_pool, url, error or ResponseError(cause))\nurllib3.exceptions.MaxRetryError: HTTPSConnectionPool(host=\'api.github.com\', port=443): Max retries exceeded with url: /repos/morpheus65535/Bazarr/releases (Caused by NewConnectionError(\'<urllib3.connection.VerifiedHTTPSConnection object at 0x7f55e94f2cd0>: Failed to establish a new connection: [Errno 111] Connection refused\'))\n\nDuring handling of the above exception, another exception occurred:\n\nTraceback (most recent call last):\n  File "/app/bazarr/bazarr/check_update.py", line 19, in check_releases\n    r = requests.get(url_releases, allow_redirects=True)\n  File "/app/bazarr/bazarr/../libs/requests/api.py", line 75, in get\n    return request(\'get\', url, params=params, **kwargs)\n  File "/app/bazarr/bazarr/../libs/requests/api.py", line 60, in request\n    return session.request(method=method, url=url, **kwargs)\n  File "/app/bazarr/bazarr/../libs/requests/sessions.py", line 533, in request\n    resp = self.send(prep, **send_kwargs)\n  File "/app/bazarr/bazarr/../libs/requests/sessions.py", line 646, in send\n    r = adapter.send(request, **kwargs)\n  File "/app/bazarr/bazarr/../libs/requests/adapters.py", line 516, in send\n    raise ConnectionError(e, request=request)\nrequests.exceptions.ConnectionError: HTTPSConnectionPool(host=\'api.github.com\', port=443): Max retries exceeded with url: /repos/morpheus65535/Bazarr/releases (Caused by NewConnectionError(\'<urllib3.connection.VerifiedHTTPSConnection object at 0x7f55e94f2cd0>: Failed to establish a new connection: [Errno 111] Connection refused\'))'|
01/04/2021 10:05:56|INFO    |root                            |BAZARR is started and waiting for request on http://0.***.***.***:6767/bazarr|
01/04/2021 10:16:20|INFO    |root                            |BAZARR is started and waiting for request on http://0.***.***.***:6767/bazarr|
